<?xml version="1.0" encoding="UTF-8"?>
<!-- Generated by org.testng.reporters.JUnitReportReporter -->
<testsuite skipped="0" hostname="HPaf008ax" name="com.guru99.testCases.tc_01_LoginTest" tests="5" failures="1" timestamp="2020-10-22T18:12:29 IST" time="13.775" errors="0">
  <testcase name="verifyTitle" time="0.034" classname="com.guru99.testCases.tc_01_LoginTest">
    <failure type="java.lang.AssertionError" message="Test Failed expected [true] but found [false]">
      <![CDATA[java.lang.AssertionError: Test Failed expected [true] but found [false]
at org.testng.Assert.fail(Assert.java:99)
at org.testng.Assert.failNotEquals(Assert.java:1037)
at org.testng.Assert.assertTrue(Assert.java:45)
at com.guru99.testCases.tc_01_LoginTest.verifyTitle(tc_01_LoginTest.java:56)
at sun.reflect.NativeMethodAccessorImpl.invoke0(Native Method)
at sun.reflect.NativeMethodAccessorImpl.invoke(Unknown Source)
at sun.reflect.DelegatingMethodAccessorImpl.invoke(Unknown Source)
at java.lang.reflect.Method.invoke(Unknown Source)
at org.testng.internal.MethodInvocationHelper.invokeMethod(MethodInvocationHelper.java:132)
at org.testng.internal.TestInvoker.invokeMethod(TestInvoker.java:599)
at org.testng.internal.TestInvoker.invokeTestMethod(TestInvoker.java:174)
at org.testng.internal.MethodRunner.runInSequence(MethodRunner.java:46)
at org.testng.internal.TestInvoker$MethodInvocationAgent.invoke(TestInvoker.java:822)
at org.testng.internal.TestInvoker.invokeTestMethods(TestInvoker.java:147)
at org.testng.internal.TestMethodWorker.invokeTestMethods(TestMethodWorker.java:146)
at org.testng.internal.TestMethodWorker.run(TestMethodWorker.java:128)
at java.util.ArrayList.forEach(Unknown Source)
at org.testng.TestRunner.privateRun(TestRunner.java:764)
at org.testng.TestRunner.run(TestRunner.java:585)
at org.testng.SuiteRunner.runTest(SuiteRunner.java:384)
at org.testng.SuiteRunner.access$000(SuiteRunner.java:28)
at org.testng.SuiteRunner$SuiteWorker.run(SuiteRunner.java:425)
at org.testng.internal.thread.ThreadUtil.lambda$execute$0(ThreadUtil.java:66)
at java.util.concurrent.FutureTask.run(Unknown Source)
at java.util.concurrent.ThreadPoolExecutor.runWorker(Unknown Source)
at java.util.concurrent.ThreadPoolExecutor$Worker.run(Unknown Source)
at java.lang.Thread.run(Unknown Source)
]]>
    </failure>
  </testcase> <!-- verifyTitle -->
  <system-out/>
  <testcase name="invalidLoginTest" time="2.786" classname="com.guru99.testCases.tc_01_LoginTest"/>
  <system-out/>
  <testcase name="invalidLoginTest" time="3.819" classname="com.guru99.testCases.tc_01_LoginTest"/>
  <system-out/>
  <testcase name="invalidLoginTest" time="3.392" classname="com.guru99.testCases.tc_01_LoginTest"/>
  <system-out/>
  <testcase name="validLoginTest" time="3.744" classname="com.guru99.testCases.tc_01_LoginTest"/>
  <system-out/>
</testsuite> <!-- com.guru99.testCases.tc_01_LoginTest -->
